Traceback (most recent call last):
  File "C:/Users/kyuree/dev/ai601/models/GAT.py", line 93, in <module>
    logits = model(graph, features)
  File "C:\Users\kyuree\Anaconda3\envs\ai601_env\lib\site-packages\torch\nn\modules\module.py", line 541, in __call__
    result = self.forward(*input, **kwargs)
  File "C:/Users/kyuree/dev/ai601/models/GAT.py", line 36, in forward
    h = self.layers[l](graph, h).flatten(1)
  File "C:\Users\kyuree\Anaconda3\envs\ai601_env\lib\site-packages\torch\nn\modules\module.py", line 541, in __call__
    result = self.forward(*input, **kwargs)
  File "C:\Users\kyuree\Anaconda3\envs\ai601_env\lib\site-packages\dgl\nn\pytorch\conv\gatconv.py", line 103, in forward
    feat = self.fc(h).view(-1, self._num_heads, self._out_feats)
  File "C:\Users\kyuree\Anaconda3\envs\ai601_env\lib\site-packages\torch\nn\modules\module.py", line 541, in __call__
    result = self.forward(*input, **kwargs)
  File "C:\Users\kyuree\Anaconda3\envs\ai601_env\lib\site-packages\torch\nn\modules\linear.py", line 87, in forward
    return F.linear(input, self.weight, self.bias)
  File "C:\Users\kyuree\Anaconda3\envs\ai601_env\lib\site-packages\torch\nn\functional.py", line 1372, in linear
    output = input.matmul(weight.t())
RuntimeError: size mismatch, m1: [3327 x 192], m2: [64 x 192] at C:\w\1\s\tmp_conda_3.7_160731\conda\conda-bld\pytorch_1570810122324\work\aten\src\TH/generic/THTensorMath.cpp:197
